<?xml version="1.0" ?>
<sdf version="1.7">
    <world name="diff_drive_world">
        <physics name="1ms" type="ignored">
            <max_step_size>0.001</max_step_size>
            <real_time_factor>1.0</real_time_factor>
        </physics>
        <plugin filename="libignition-gazebo-physics-system.so" name="ignition::gazebo::systems::Physics">
        </plugin>
        <plugin filename="libignition-gazebo-user-commands-system.so" name="ignition::gazebo::systems::UserCommands">
        </plugin>
        <plugin filename="libignition-gazebo-scene-broadcaster-system.so" name="ignition::gazebo::systems::SceneBroadcaster">
        </plugin>

        <gui fullscreen="1">
            <!-- 3D scene -->
            <plugin filename="GzScene3D" name="3D View">
                <ignition-gui>
                    <title>3D View</title>
                    <property type="bool" key="showTitleBar">false</property>
                    <property type="string" key="state">docked</property>
                </ignition-gui>

                <engine>ogre2</engine>
                <scene>scene</scene>
                <ambient_light>0.4 0.4 0.4</ambient_light>
                <background_color>0.8 0.8 0.8</background_color>
                <camera_pose>-1 -2 2 0 0.8 0.8</camera_pose> <!-- it took me so long to find out how this works, since its not in the spec -->
  
            </plugin>

            <!-- World control -->
            <plugin filename="WorldControl" name="World control">
                <ignition-gui>
                    <title>World control</title>
                    <property type="bool" key="showTitleBar">false</property>
                    <property type="bool" key="resizable">false</property>
                    <property type="double" key="height">72</property>
                    <property type="double" key="width">121</property>
                    <property type="double" key="z">1</property>

                    <property type="string" key="state">floating</property>
                    <anchors target="3D View">
                        <line own="left" target="left"/>
                        <line own="bottom" target="bottom"/>
                    </anchors>
                </ignition-gui>

                <play_pause>true</play_pause>
                <step>true</step>
                <start_paused>true</start_paused>
                <service>/world/diff_drive_world/control</service>
                <stats_topic>/world/diff_drive_world/stats</stats_topic>
            </plugin>

            <!-- World statistics -->
            <plugin filename="WorldStats" name="World stats">
                <ignition-gui>
                    <title>World stats</title>
                    <property type="bool" key="showTitleBar">false</property>
                    <property type="bool" key="resizable">false</property>
                    <property type="double" key="height">110</property>
                    <property type="double" key="width">290</property>
                    <property type="double" key="z">1</property>

                    <property type="string" key="state">floating</property>
                    <anchors target="3D View">
                        <line own="right" target="right"/>
                        <line own="bottom" target="bottom"/>
                    </anchors>
                </ignition-gui>

                <sim_time>true</sim_time>
                <real_time>true</real_time>
                <real_time_factor>true</real_time_factor>
                <iterations>true</iterations>
                <topic>/world/diff_drive_world/stats</topic>
            </plugin>

            <!-- Entity tree -->
            <plugin filename="EntityTree" name="Entity tree">
            </plugin>

            <!-- Camera does not work as of now! (IGN Gazebo)
                    see: https://github.com/ignitionrobotics/ign-gazebo/issues/421
             -->
            <camera name="user_camera">
                <pose>0 0 0 0 0 0</pose>
            </camera>

            
        </gui>

        <light type="directional" name="sun">
            <cast_shadows>true</cast_shadows>
            <pose>0 0 10 0 0 0</pose>
            <diffuse>0.8 0.8 0.8 1</diffuse>
            <specular>0.2 0.2 0.2 1</specular>
            <attenuation>
                <range>1000</range>
                <constant>0.9</constant>
                <linear>0.01</linear>
                <quadratic>0.001</quadratic>
            </attenuation>
            <direction>-0.5 0.1 -0.9</direction>
        </light>

        <model name="ground_plane">
            <static>true</static>
            <link name="link">
                <collision name="collision">
                    <geometry>
                        <plane>
                            <normal>0 0 1</normal>
                        </plane>
                    </geometry>
                </collision>
                <visual name="visual">
                    <geometry>
                        <plane>
                            <normal>0 0 1</normal>
                            <size>1 1 1</size>
                        </plane>
                    </geometry>
                    <material>
                        <ambient>0.8 0.8 0.8 1</ambient>
                        <diffuse>0.8 0.8 0.8 1</diffuse>
                        <specular>0.8 0.8 0.8 1</specular>
                    </material>
                </visual>
            </link>
        </model>

        <model name="diff-drive" canonical_link='chassis'>
            <link name="chassis">
                <!--height placement is wheel radius MINUS height to stepper Axis Center (from stl origin)-->
                <pose>0 0 0.0408 0 0 1.570796</pose>
                <inertial>                    <!--inertial properties of the link mass, inertia matix-->
                    <mass>1.5</mass>
                    <inertia>
                        <ixx>1</ixx>
                        <ixy>0</ixy>
                        <ixz>0</ixz>
                        <iyy>0.381317</iyy>
                        <iyz>0</iyz>
                        <izz>1</izz>
                    </inertia>
                </inertial>
                <visual name='visual'>
                    <geometry>
                        <mesh>
                            <uri>mesh/v003/diff-drive_base.dae</uri>
                            <scale>1 1 1</scale>
                        </mesh>
                    </geometry>
                    <!--let's add color to our link-->
                    <material>
                        <ambient>0.6 0.6 0.6 1</ambient>
                        <diffuse>0.6 0.6 0.6 1</diffuse>
                        <specular>0.6 0.6 0.6 1</specular>
                    </material>
                </visual>
                <collision name='collision'>
                    <geometry>
                        <mesh>
                            <uri>mesh/v003/diff-drive_base.dae</uri>
                            <scale>1 1 1</scale>
                        </mesh>
                    </geometry>

                </collision>
            </link>
            <link name='left_wheel'>
                <!--NOTE: width of the chassis is 160mm, width of wheel is approx. 37.5mm this offet needs to be at least 98.5mm-->
                <!--NOTE: the stepper Axis Center is at a height distance of 23.5 from the bottom base plate side-->
                <!--NOTE: the stepper Axis Center is at a width distance of YET TO BE DETERMINED from stl origin-->
                <pose relative_to="chassis">0.1 0.0459 0.02893 0 -1.5707 3.14159</pose>
                <inertial>
                    <mass>0.35</mass>
                    <inertia>
                        <ixx>0.043333</ixx>
                        <ixy>0</ixy>
                        <ixz>0</ixz>
                        <iyy>0.043333</iyy>
                        <iyz>0</iyz>
                        <izz>0.08</izz>
                    </inertia>
                </inertial>
                <visual name='visual'>
                    <geometry>
                        <mesh>
                            <uri>
                                mesh/v003/wheel.dae
                            </uri>
                            <scale>1 1 1</scale>
                        </mesh>
                    </geometry>
                    <material>
                        <ambient>0.6 0.6 0.6 1</ambient>
                        <diffuse>0.6 0.6 0.6 1</diffuse>
                        <specular>0.6 0.6 0.6 1</specular>
                    </material>
                </visual>
                <collision name='collision'>
                    <geometry>
                        <mesh>
                            <uri>
                                mesh/v003/wheel.dae
                            </uri>
                            <scale>1 1 1</scale>
                        </mesh>
                    </geometry>
                </collision>
            </link>
            <!--The same as left wheel but with different position-->
            <link name='right_wheel'>
                <pose relative_to="chassis">-0.1 0.0459 0.02893 0 -1.5707 0</pose>                <!--angles are in radian-->
                <inertial>
                    <mass>0.35</mass>
                    <inertia>
                        <ixx>0.043333</ixx>
                        <ixy>0</ixy>
                        <ixz>0</ixz>
                        <iyy>0.043333</iyy>
                        <iyz>0</iyz>
                        <izz>0.08</izz>
                    </inertia>
                </inertial>
                <visual name='visual'>
                    <geometry>
                        <mesh>
                            <uri>
                                mesh/v003/wheel.dae
                            </uri>
                            <scale>1 1 1</scale>
                        </mesh>
                    </geometry>
                    <material>
                        <ambient>0.6 0.6 0.6 1</ambient>
                        <diffuse>0.6 0.6 0.6 1</diffuse>
                        <specular>0.6 0.6 0.6 1</specular>
                    </material>
                </visual>
                <collision name='collision'>
                    <geometry>
                        <mesh>
                            <uri>
                                mesh/v003/wheel.dae
                            </uri>
                            <scale>1 1 1</scale>
                        </mesh>
                    </geometry>
                </collision>
            </link>
            <!-- frame tag allows for a new reference frame for an entity an entitiys' frame needs to be linked to the custom created frame -->
            <frame name="caster_frame" attached_to='chassis'>
                <pose>0 -0.065 -0.0055 0 0 0</pose>
            </frame>
            <!--caster wheel-->
            <link name='caster'>
                <pose relative_to='caster_frame'/>
                <inertial>
                    <mass>0.05</mass>
                    <inertia>
                        <ixx>0.006</ixx>
                        <ixy>0</ixy>
                        <ixz>0</ixz>
                        <iyy>0.006</iyy>
                        <iyz>0</iyz>
                        <izz>0.006</izz>
                    </inertia>
                </inertial>
                <visual name='visual'>
                    <geometry>
                        <sphere>
                            <radius>0.007</radius>
                        </sphere>
                    </geometry>
                    <material>
                        <ambient>0.8 0.8 0.8 1</ambient>
                        <diffuse>0.8 0.8 0.8 1</diffuse>
                        <specular>0.8 0.8 0.8 1</specular>
                    </material>
                </visual>
                <collision name='collision'>
                    <geometry>
                        <sphere>
                            <radius>0.007</radius>
                        </sphere>
                    </geometry>
                </collision>
            </link>
            <joint name='left_wheel_joint' type='revolute'>
                <pose relative_to='left_wheel'/>
                <parent>chassis</parent>
                <child>left_wheel</child>
                <axis>
                    <xyz expressed_in='__model__'>0 1 0</xyz>                    <!--can be defined as any frame or even arbitrary frames-->
                    <limit>
                        <lower>-1.79769e+308</lower>                        <!--negative infinity-->
                        <upper>1.79769e+308</upper>                        <!--positive infinity-->
                    </limit>
                </axis>
            </joint>
            <joint name='right_wheel_joint' type='revolute'>
                <pose relative_to='right_wheel'/>
                <parent>chassis</parent>
                <child>right_wheel</child>
                <axis>
                    <xyz expressed_in='__model__'>0 1 0</xyz>
                    <limit>
                        <lower>-1.79769e+308</lower>                        <!--negative infinity-->
                        <upper>1.79769e+308</upper>                        <!--positive infinity-->
                    </limit>
                </axis>
            </joint>
            <joint name='caster_wheel' type='ball'>
                <parent>chassis</parent>
                <child>caster</child>
            </joint>
            <!-- plugin information from: https://ignitionrobotics.org/docs/citadel/moving_robot -->
            <plugin filename="libignition-gazebo-diff-drive-system.so" name="ignition::gazebo::systems::DiffDrive">
                <left_joint>left_wheel_joint</left_joint>
                <right_joint>right_wheel_joint</right_joint>
                <wheel_separation>0.2</wheel_separation>
                <wheel_radius>0.0408</wheel_radius>
                <odom_publish_frequency>1</odom_publish_frequency>
                <topic>/diff_drive/cmd_vel</topic>
            </plugin>
        </model>
    </world>
</sdf>
